Traceback (most recent call last):
  File "C:\Users\SamGostarCO\AppData\Local\Programs\Python\Python311\Lib\site-packages\jupyter_cache\executors\utils.py", line 58, in single_nb_execution
    executenb(
  File "C:\Users\SamGostarCO\AppData\Local\Programs\Python\Python311\Lib\site-packages\nbclient\client.py", line 1319, in execute
    return NotebookClient(nb=nb, resources=resources, km=km, **kwargs).execute()
           ^^^^^^^^^^^^^^^^^^^^^^^^^^^^^^^^^^^^^^^^^^^^^^^^^^^^^^^^^^^^^^^^^^^^^
  File "C:\Users\SamGostarCO\AppData\Roaming\Python\Python311\site-packages\jupyter_core\utils\__init__.py", line 165, in wrapped
    return loop.run_until_complete(inner)
           ^^^^^^^^^^^^^^^^^^^^^^^^^^^^^^
  File "C:\Users\SamGostarCO\AppData\Local\Programs\Python\Python311\Lib\asyncio\base_events.py", line 654, in run_until_complete
    return future.result()
           ^^^^^^^^^^^^^^^
  File "C:\Users\SamGostarCO\AppData\Local\Programs\Python\Python311\Lib\site-packages\nbclient\client.py", line 709, in async_execute
    await self.async_execute_cell(
  File "C:\Users\SamGostarCO\AppData\Local\Programs\Python\Python311\Lib\site-packages\nbclient\client.py", line 1062, in async_execute_cell
    await self._check_raise_for_error(cell, cell_index, exec_reply)
  File "C:\Users\SamGostarCO\AppData\Local\Programs\Python\Python311\Lib\site-packages\nbclient\client.py", line 918, in _check_raise_for_error
    raise CellExecutionError.from_cell_and_msg(cell, exec_reply_content)
nbclient.exceptions.CellExecutionError: An error occurred while executing the following cell:
------------------
# Import libraries
import pickle
import matplotlib.pyplot as plt
import  pandas as pd
from IPython.display import Image, display

import econml
import dowhy
from dowhy import CausalModel
# Load Data
df =pd.read_pickle( open( "df_causal_inference.p", "rb" ) )
------------------


[31m---------------------------------------------------------------------------[39m
[31mFileNotFoundError[39m                         Traceback (most recent call last)
[36mCell[39m[36m [39m[32mIn[1][39m[32m, line 11[39m
[32m      9[39m [38;5;28;01mfrom[39;00m[38;5;250m [39m[34;01mdowhy[39;00m[38;5;250m [39m[38;5;28;01mimport[39;00m CausalModel
[32m     10[39m [38;5;66;03m# Load Data[39;00m
[32m---> [39m[32m11[39m df =pd.read_pickle( [38;5;28;43mopen[39;49m[43m([49m[43m [49m[33;43m"[39;49m[33;43mdf_causal_inference.p[39;49m[33;43m"[39;49m[43m,[49m[43m [49m[33;43m"[39;49m[33;43mrb[39;49m[33;43m"[39;49m[43m [49m[43m)[49m )

[36mFile [39m[32m~\AppData\Roaming\Python\Python311\site-packages\IPython\core\interactiveshell.py:326[39m, in [36m_modified_open[39m[34m(file, *args, **kwargs)[39m
[32m    319[39m [38;5;28;01mif[39;00m file [38;5;129;01min[39;00m {[32m0[39m, [32m1[39m, [32m2[39m}:
[32m    320[39m     [38;5;28;01mraise[39;00m [38;5;167;01mValueError[39;00m(
[32m    321[39m         [33mf[39m[33m"[39m[33mIPython won[39m[33m'[39m[33mt let you open fd=[39m[38;5;132;01m{[39;00mfile[38;5;132;01m}[39;00m[33m by default [39m[33m"[39m
[32m    322[39m         [33m"[39m[33mas it is likely to crash IPython. If you know what you are doing, [39m[33m"[39m
[32m    323[39m         [33m"[39m[33myou can use builtins[39m[33m'[39m[33m open.[39m[33m"[39m
[32m    324[39m     )
[32m--> [39m[32m326[39m [38;5;28;01mreturn[39;00m [43mio_open[49m[43m([49m[43mfile[49m[43m,[49m[43m [49m[43m*[49m[43margs[49m[43m,[49m[43m [49m[43m*[49m[43m*[49m[43mkwargs[49m[43m)[49m

[31mFileNotFoundError[39m: [Errno 2] No such file or directory: 'df_causal_inference.p'

